Traceback (most recent call last):
  File "/Users/saravana.kumar/opt/anaconda3/envs/algo/lib/python3.8/site-packages/pandas/core/indexes/base.py", line 2895, in get_loc
    return self._engine.get_loc(casted_key)
  File "pandas/_libs/index.pyx", line 70, in pandas._libs.index.IndexEngine.get_loc
  File "pandas/_libs/index.pyx", line 101, in pandas._libs.index.IndexEngine.get_loc
  File "pandas/_libs/hashtable_class_helper.pxi", line 1675, in pandas._libs.hashtable.PyObjectHashTable.get_item
  File "pandas/_libs/hashtable_class_helper.pxi", line 1683, in pandas._libs.hashtable.PyObjectHashTable.get_item
KeyError: 'status'

The above exception was the direct cause of the following exception:

Traceback (most recent call last):
  File "square_off.py", line 75, in <module>
    pending = [j for j in pending if j not in drop]
  File "/Users/saravana.kumar/opt/anaconda3/envs/algo/lib/python3.8/site-packages/pandas/core/frame.py", line 2906, in __getitem__
    indexer = self.columns.get_loc(key)
  File "/Users/saravana.kumar/opt/anaconda3/envs/algo/lib/python3.8/site-packages/pandas/core/indexes/base.py", line 2897, in get_loc
    raise KeyError(key) from err
KeyError: 'status'
